<?xml version="1.0"?>
<robot xmlns:xacro="http://ros.org/wiki/xacro" name="my_robo" >

 <xacro:include filename="$(find simc)/urdf/common.xacro"/>
 <xacro:property name="M_PI" value="3.14159274"/>
<xacro:property name="mu" value="0.5"/>


 <link name="base_link">
    <box_create mass="10" height="0.1" width="0.8" depth="0.8"/>

 </link>

<unit_create base_name="left_front_steering" wheel_name="left_front_wheel"/>

  <joint name="left_front_steering_joint" type="continuous">
    <parent link="base_link"/>
    <child link="left_front_steering"/>
    <origin rpy="0 0 0" xyz="0.35 0.35 -0.055"/>
    <axis xyz="0 0 1"/>
  </joint>

  <joint name="left_front_wheel_joint" type="continuous">
    <parent link="left_front_steering"/>
    <child link="left_front_wheel"/>
    <origin rpy="0 0 0" xyz="0 0 -0.055"/>
    <axis xyz="0 1 0"/>
  </joint>



<unit_create base_name="left_rear_steering" wheel_name="left_rear_wheel"/>

  <joint name="left_rear_steering_joint" type="continuous">
    <parent link="base_link"/>
    <child link="left_rear_steering"/>
    <origin rpy="0 0 0" xyz="-0.35 0.35 -0.055"/>
    <axis xyz="0 0 1"/>
  </joint>

  <joint name="left_rear_wheel_joint" type="continuous">
    <parent link="left_rear_steering"/>
    <child link="left_rear_wheel"/>
    <origin rpy="0 0 0" xyz="0 0 -0.055"/>
    <axis xyz="0 1 0"/>
  </joint>


<unit_create base_name="right_front_steering" wheel_name="right_front_wheel"/>

  <joint name="right_front_steering_joint" type="continuous">
    <parent link="base_link"/>
    <child link="right_front_steering"/>
    <origin rpy="0 0 0" xyz="0.35 -0.35 -0.055"/>
    <axis xyz="0 0 1"/>
  </joint>

  <joint name="right_front_wheel_joint" type="continuous">
    <parent link="right_front_steering"/>
    <child link="right_front_wheel"/>
    <origin rpy="0 0 0" xyz="0 0 -0.055"/>
    <axis xyz="0 1 0"/>
  </joint>



<unit_create base_name="right_rear_steering" wheel_name="right_rear_wheel"/>


  <joint name="right_rear_steering_joint" type="continuous">
    <parent link="base_link"/>
    <child link="right_rear_steering"/>
    <origin rpy="0 0 0" xyz="-0.35 -0.35 -0.055"/>
    <axis xyz="0 0 1"/>
  </joint>

  <joint name="right_rear_wheel_joint" type="continuous">
    <parent link="right_rear_steering"/>
    <child link="right_rear_wheel"/>
    <origin rpy="0 0 0" xyz="0 0 -0.055"/>
    <axis xyz="0 1 0"/>
  </joint>



<link name="base_footprint"/>
  <joint name="base_joint" type="fixed">
   <parent link="base_footprint"/>
   <child link="base_link"/>
   <origin rpy="0 0 0" xyz="0 0 0.16"/>

 </joint>


  <!-- Hokuyo Laser -->
  <link name="left_hokuyo_link">
    <collision>
      <origin xyz="0 0 0" rpy="0 0 0"/>
      <geometry>
        <box size="0.1 0.1 0.1"/>
      </geometry>
    </collision>

    <visual>
      <origin xyz="0 0 0" rpy="0 0 0"/>
      <geometry>
        <mesh filename="package://rrbot_description/meshes/hokuyo.dae"/>
      </geometry>
    </visual>


  </link>
  <joint name="left_hokuyo_joint" type="fixed">
    <axis xyz="0 1 0" />
    <origin xyz="0.4 0.4 0.1" rpy="0 0 ${M_PI/4}"/>
    <parent link="base_link"/>
    <child link="left_hokuyo_link"/>
  </joint>

  <!-- Hokuyo Laser -->
  <link name="right_hokuyo_link">
    <collision>
      <origin xyz="0 0 0" rpy="0 0 0"/>
      <geometry>
        <box size="0.1 0.1 0.1"/>
      </geometry>
    </collision>

    <visual>
      <origin xyz="0 0 0" rpy="0 0 0"/>
      <geometry>
        <mesh filename="package://rrbot_description/meshes/hokuyo.dae"/>
      </geometry>
    </visual>


  </link>
  <joint name="right_hokuyo_joint" type="fixed">
    <axis xyz="0 1 0" />
    <origin xyz="-0.4 -0.4 0.1" rpy="0 0 ${-3*M_PI/4}"/>
    <parent link="base_link"/>
    <child link="right_hokuyo_link"/>
  </joint>


  <!-- ===============  Transmission ===============-->
 <trans_create base_joint_name="left_front_steering_joint" wheel_name="left_front_wheel"/>
<trans_create base_joint_name="left_rear_steering_joint" wheel_name="left_rear_wheel"/>
<trans_create base_joint_name="right_front_steering_joint" wheel_name="right_front_wheel"/>
<trans_create base_joint_name="right_rear_steering_joint" wheel_name="right_rear_wheel"/>





  <!-- =============== Gazebo =============== -->
  <gazebo>
    <plugin name="gazebo_ros_control" filename="libgazebo_ros_control.so">
      <robotNamespace>my_robo</robotNamespace>
    </plugin>
  </gazebo>

 <gazebo reference="base_link">
   <selfCollide>true</selfCollide>
    <mu1 value="${mu}" />
    <mu2 value="${mu}" />
  </gazebo>

 <gazebo reference="left_front_steering">
   <selfCollide>true</selfCollide>
     <!-- This caster is no frictional resistance. -->
      <mu1 value="${mu}" />
    <mu2 value="${mu}" />
  </gazebo>

<gazebo reference="left_front_wheel">
   <selfCollide>true</selfCollide>
     <!-- This caster is no frictional resistance. -->
    <mu1 value="${mu}" />
    <mu2 value="${mu}" />
  </gazebo>



 <gazebo reference="left_rear_steering">
   <selfCollide>true</selfCollide>
     <!-- This caster is no frictional resistance. -->
    <mu1 value="${mu}" />
    <mu2 value="${mu}" />
  </gazebo>

<gazebo reference="left_rear_wheel">
   <selfCollide>true</selfCollide>
     <!-- This caster is no frictional resistance. -->
    <mu1 value="${mu}" />
    <mu2 value="${mu}" />
  </gazebo>

 <gazebo reference="right_front_steering">
   <selfCollide>true</selfCollide>
     <!-- This caster is no frictional resistance. -->
    <mu1 value="${mu}" />
    <mu2 value="${mu}" />
  </gazebo>

<gazebo reference="right_front_wheel">
   <selfCollide>true</selfCollide>
     <!-- This caster is no frictional resistance. -->
    <mu1 value="${mu}" />
    <mu2 value="${mu}" />
</gazebo>
 <gazebo reference="right_rear_steering">
   <selfCollide>true</selfCollide>
     <!-- This caster is no frictional resistance. -->
    <mu1 value="${mu}" />
    <mu2 value="${mu}" />
  </gazebo>

<gazebo reference="right_rear_wheel">
   <selfCollide>true</selfCollide>
     <!-- This caster is no frictional resistance. -->
    <mu1 value="${mu}" />
    <mu2 value="${mu}" />
  </gazebo>

  <!-- hokuyo -->
  <gazebo reference="left_hokuyo_link">
    <sensor type="ray" name="left_hokuyo_sensor">
      <pose>0 0 0 0 0 0</pose>
      <visualize>false</visualize>
      <update_rate>40</update_rate>
      <ray>
        <scan>
          <horizontal>
            <samples>720</samples>
            <resolution>1</resolution>
            <min_angle>-1.570796</min_angle>
            <max_angle>1.570796</max_angle>
          </horizontal>
        </scan>
        <range>
          <min>0.10</min>
          <max>30.0</max>
          <resolution>0.01</resolution>
        </range>
        <noise>
          <type>gaussian</type>
          <!-- Noise parameters based on published spec for Hokuyo laser
               achieving "+-30mm" accuracy at range < 10m.  A mean of 0.0m and
               stddev of 0.01m will put 99.7% of samples within 0.03m of the true
               reading. -->
          <mean>0.0</mean>
          <stddev>0.01</stddev>
        </noise>
      </ray>
      <plugin name="gazebo_ros_left_hokuyo_controller" filename="libgazebo_ros_laser.so">
        <topicName>/rrbot/laser/left_scan</topicName>
        <frameName>left_hokuyo_link</frameName>
      </plugin>
    </sensor>
  </gazebo>


  <!-- hokuyo -->
  <gazebo reference="right_hokuyo_link">
    <sensor type="ray" name="right_hokuyo_sensor">
      <pose>0 0 0 0 0 0</pose>
      <visualize>false</visualize>
      <update_rate>40</update_rate>
      <ray>
        <scan>
          <horizontal>
            <samples>720</samples>
            <resolution>1</resolution>
            <min_angle>-1.570796</min_angle>
            <max_angle>1.570796</max_angle>
          </horizontal>
        </scan>
        <range>
          <min>0.10</min>
          <max>30.0</max>
          <resolution>0.01</resolution>
        </range>
        <noise>
          <type>gaussian</type>
          <!-- Noise parameters based on published spec for Hokuyo laser
               achieving "+-30mm" accuracy at range < 10m.  A mean of 0.0m and
               stddev of 0.01m will put 99.7% of samples within 0.03m of the true
               reading. -->
          <mean>0.0</mean>
          <stddev>0.01</stddev>
        </noise>
      </ray>
      <plugin name="gazebo_ros_right_hokuyo_controller" filename="libgazebo_ros_laser.so">
        <topicName>/rrbot/laser/right_scan</topicName>
        <frameName>right_hokuyo_link</frameName>
      </plugin>
    </sensor>
  </gazebo>

</robot>
